<mujoco model="xMateSR4C">
    <compiler angle="radian" meshdir="../stl/" autolimits="true" balanceinertia="true"/>
  <option gravity="0 0 -9.81"/>

  <asset>
    <material name="white" rgba="1.0 1.0 1.0 1.0"/>
    <mesh name="base_mesh" file="xMateSR4C_base.stl" scale="0.001 0.001 0.001"/>
    <mesh name="link1_mesh" file="xMateSR4C_link1.stl" scale="0.001 0.001 0.001"/>
    <mesh name="link2_mesh" file="xMateSR4C_link2.stl" scale="0.001 0.001 0.001"/>
    <mesh name="link3_mesh" file="xMateSR4C_link3.stl" scale="0.001 0.001 0.001"/>
    <mesh name="link4_mesh" file="xMateSR4C_link4.stl" scale="0.001 0.001 0.001"/>
    <mesh name="link5_mesh" file="xMateSR4C_link5.stl" scale="0.001 0.001 0.001"/>
    <mesh name="link6_mesh" file="xMateSR4C_link6.stl" scale="0.001 0.001 0.001"/>
  </asset>

  <worldbody>
    <light pos="0 0 1.5" dir="0 0 -1" directional="true"/>
    <geom name="floor" type="plane" size="2 2 0.1" rgba="0.8 0.9 0.8 1"/>

    <body name="xMateSR4C_base" pos="0 0 0">
      <inertial pos="-0.000072769597 -0.001679187012 0.002986854502" mass="3.44074938" fullinertia="0.01764837 0.016617391 1.120163944 0 0 -0.002218013"/>
      <geom type="mesh" mesh="base_mesh" material="white"/>

      <body name="xMateSR4C_link1" pos="0 0 0">
        <inertial pos="1.09999999999679e-05 -0.00799199999999364 -0.0921580000000931" mass="3.16699999486378" fullinertia="0.0311679899460595 0.0307127099468431 0.00587739998995415 -6.49999998879087e-07 -4.26999999258665e-06 -0.00223655999611672"/>
        <joint name="xmate_joint_1" type="hinge" axis="0 0 1" range="-3.1416 3.1416" limited="true" damping="0.5"/>
        <geom type="mesh" mesh="link1_mesh" material="white" pos="0 0 0.355"/>

        <body name="xMateSR4C_link2" pos="0 0 0.355">
          <inertial pos="0.169304139589595 -0.0167375750841445 -0.0698168604257776" mass="3.89505775503759" fullinertia="0.0179531824691758 0.132852985273582 0.138139839236999 0.0309224033095523 -0.00240843390062569 0.00071426442226283"/>
          <joint name="xmate_joint_2" type="hinge" axis="0 1 0" range="-2.4222 2.35619" limited="true" damping="0.5"/>
          <geom type="mesh" mesh="link2_mesh" material="white"/>

          <body name="xMateSR4C_link3" pos="0.05 0 0.4">
            <inertial pos="-0.00101677311184785 0.0992317670799201 -0.00599764278732221" mass="1.55161965449885" fullinertia="0.0205839772508243 0.00322986952841047 0.0202148376332874 0.0034186607558711 0.000323904256666548 0.00178215039218484"/>
            <joint name="xmate_joint_3" type="hinge" axis="0 -1 0" range="-2.96555 2.35619" limited="true" damping="0.5"/>
            <geom type="mesh" mesh="link3_mesh" material="white"/>

            <body name="xMateSR4C_link4" pos="-0.05 0 0.4">
              <inertial pos="-2.50011383739252e-05 -0.0109230011023275 -0.071266999970154" mass="1.8819999954753" fullinertia="0.0133198499755109 0.0125198899767503 0.00278827999533888 -1.85000009038544e-06 8.69999115245914e-07 -0.00143893999778065"/>
              <joint name="xmate_joint_4" type="hinge" axis="0 0 1" range="-3.1416 3.1416" limited="true" damping="0.5"/>
              <geom type="mesh" mesh="link4_mesh" material="white"/>

              <body name="xMateSR4C_link5" pos="0 0.136 0">
                <inertial pos="-0.00141300709545952 0.0118448713738878 -0.0209142000136706" mass="1.34621855234916" fullinertia="0.00490782058915933 0.00384857289176222 0.00258053503197348 -1.04779487811945e-05 -9.95872429112993e-06 0.000384368912752211"/>
                <joint name="xmate_joint_5" type="hinge" axis="0 -1 0" range="-3.1416 3.1416" limited="true" damping="0.5"/>
                <geom type="mesh" mesh="link5_mesh" material="white"/>

                <body name="xMateSR4C_link6" pos="0 0 0.1035">
                  <inertial pos="7.29993135608786e-05 7.90001800890199e-05 -0.044852999792348" mass="0.633999997351584" fullinertia="0.000997019998284638 0.00100252999827485 0.000447949999234091 -1.37999999641383e-06 8.99999979434996e-07 1.5800000042753e-06"/>
                  <joint name="xmate_joint_6" type="hinge" axis="0 0 1" range="-3.14 3.14" limited="true" damping="0.5"/>
                  <geom type="mesh" mesh="link6_mesh" material="white"/>
                </body>
              </body>
            </body>
          </body>
        </body>
      </body>
    </body>
  </worldbody>

  <actuator>
    <motor name="motor1" joint="xmate_joint_1" gear="1" ctrllimited="true" ctrlrange="-300 300"/>
    <motor name="motor2" joint="xmate_joint_2" gear="1" ctrllimited="true" ctrlrange="-300 300"/>
    <motor name="motor3" joint="xmate_joint_3" gear="1" ctrllimited="true" ctrlrange="-300 300"/>
    <motor name="motor4" joint="xmate_joint_4" gear="1" ctrllimited="true" ctrlrange="-300 300"/>
    <motor name="motor5" joint="xmate_joint_5" gear="1" ctrllimited="true" ctrlrange="-300 300"/>
    <motor name="motor6" joint="xmate_joint_6" gear="1" ctrllimited="true" ctrlrange="-300 300"/>
  </actuator>
</mujoco>