<?xml version="1.0" ?>
<!-- =================================================================================== -->
<!-- |    This document was autogenerated by xacro from xMateSR4C.xacro                | -->
<!-- |    EDITING THIS FILE BY HAND IS NOT RECOMMENDED                                 | -->
<!-- =================================================================================== -->
<!-- xMateSR4 manipulator -->
<!--  Attention!!! inertia in the model is not correct!!! -->
<robot name="xMateSR4C" xmlns:xacro="http://www.ros.org/wiki/xacro">
  <!-- Constants for robot dimensions -->
  <material name="black">
    <color rgba="0.0 0.0 0.0 1.0"/>
  </material>
  <material name="blue">
    <color rgba="0.0 0.0 0.8 1.0"/>
  </material>
  <material name="green">
    <color rgba="0.0 0.8 0.0 1.0"/>
  </material>
  <material name="grey">
    <color rgba="0.2 0.2 0.2 1.0"/>
  </material>
  <material name="orange">
    <color rgba="1.0 0.423529411765 0.0392156862745 1.0"/>
  </material>
  <material name="brown">
    <color rgba="0.870588235294 0.811764705882 0.764705882353 1.0"/>
  </material>
  <material name="red">
    <color rgba="0.8 0.0 0.0 1.0"/>
  </material>
  <material name="white">
    <color rgba="1.0 1.0 1.0 1.0"/>
  </material>
  <material name="Beige">
    <color rgba="1.0 0.784 0.5765 1.0"/>
  </material>
  <!-- Used for fixing robot to Gazebo 'base_link' -->
  <link name="world"/>
  <joint name="fixed" type="fixed">
    <parent link="world"/>
    <child link="xMateSR4C_base"/>
  </joint>
  <!--base-->
  <link name="xMateSR4C_base">
    <visual>
      <geometry>
        <mesh filename="package://xMateSR4C_description/meshes/visual/xMateSR4C_base.stl" scale="0.001 0.001 0.001"/>
      </geometry>
      <origin rpy="0 0 0" xyz="0.0 0.0 0.0"/>
      <material name="white"/>
    </visual>
    <inertial>
      <mass value="3.44074938"/>
      <inertia ixx="0.01764837" ixy="0" ixz="0" iyy="0.016617391" iyz="-0.002218013" izz="1.120163944"/>
      <origin rpy="0 0 0" xyz="-0.000072769597 -0.001679187012 0.002986854502"/>
    </inertial>
    <collision>
      <geometry>
        <mesh filename="package://xMateSR4C_description/meshes/collision/xMateSR4C_base.stl" scale="0.001 0.001 0.001"/>
      </geometry>
      <origin rpy="0 0 0" xyz="0.0 0.0 0.0"/>
    </collision>
  </link>

  <joint name="xmate_joint_1" type="revolute">
    <parent link="xMateSR4C_base"/>
    <child link="xMateSR4C_link1"/>
    <limit effort="300" lower="-3.1416" upper="3.1416" velocity="10"/>
    <axis xyz="0 0 1"/>
    <origin rpy="0 0 0" xyz="0 0 0"/>
  </joint>
  <transmission name="tran1">
    <type>transmission_interface/SimpleTransmission</type>
    <joint name="xmate_joint_1">
      <hardwareInterface>EffortJointInterface</hardwareInterface>
    </joint>
    <actuator name="motor1">
      <hardwareInterface>EffortJointInterface</hardwareInterface>
      <mechanicalReduction>100</mechanicalReduction>
    </actuator>
  </transmission>

  <!--link 1-->
  <link name="xMateSR4C_link1">
    <visual>
      <geometry>
        <mesh filename="package://xMateSR4C_description/meshes/visual/xMateSR4C_link1.stl" scale="0.001 0.001 0.001"/>
      </geometry>
      <origin rpy="0 0 0" xyz="0 0 0.355"/>
      <material name="white"/>
    </visual>
    <inertial>
      <origin xyz="1.09999999999679e-05 -0.00799199999999364 -0.0921580000000931" rpy="0 0 0"/>
      <mass value="3.16699999486378"/>
      <inertia ixx="0.0311679899460595" ixy="-6.49999998879087e-07" ixz="-4.26999999258665e-06" iyy="0.0307127099468431" iyz="-0.00223655999611672" izz="0.00587739998995415"/>
    </inertial>
    <collision>
      <geometry>
        <mesh filename="package://xMateSR4C_description/meshes/collision/xMateSR4C_link1.stl" scale="0.001 0.001 0.001"/>
      </geometry>
      <origin rpy="0 0 0" xyz="0 0 0"/>
    </collision>
  </link>

  <joint name="xmate_joint_2" type="revolute">
    <parent link="xMateSR4C_link1"/>
    <child link="xMateSR4C_link2"/>
    <limit effort="300" lower="-2.4222" upper="2.35619" velocity="10"/>
    <axis xyz="0 1 0"/>
    <origin rpy="0 0 0" xyz="0 0 0.355"/>
  </joint>
  <transmission name="tran2">
    <type>transmission_interface/SimpleTransmission</type>
    <joint name="xmate_joint_2">
      <hardwareInterface>EffortJointInterface</hardwareInterface>
    </joint>
    <actuator name="motor2">
      <hardwareInterface>EffortJointInterface</hardwareInterface>
      <mechanicalReduction>1</mechanicalReduction>
    </actuator>
  </transmission>

  <!--link 2-->
  <link name="xMateSR4C_link2">
    <visual>
      <geometry>
        <mesh filename="package://xMateSR4C_description/meshes/visual/xMateSR4C_link2.stl" scale="0.001 0.001 0.001"/>
      </geometry>
      <origin rpy="0 0 0" xyz="0 0 0.0"/>
      <material name="white"/>
    </visual>
    <inertial>
      <origin xyz="0.169304139589595 -0.0167375750841445 -0.0698168604257776" rpy="0 0 0"/>
      <mass value="3.89505775503759"/>
      <inertia ixx="0.0179531824691758" ixy="0.0309224033095523" ixz="-0.00240843390062569" iyy="0.132852985273582" iyz="0.00071426442226283" izz="0.138139839236999"/>
    </inertial>
    <collision>
      <geometry>
        <mesh filename="package://xMateSR4C_description/meshes/collision/xMateSR4C_link2.stl" scale="0.001 0.001 0.001"/>
      </geometry>
      <origin rpy="0 0 0" xyz="0 0 0.0"/>
    </collision>
  </link>

  <joint name="xmate_joint_3" type="revolute">
    <parent link="xMateSR4C_link2"/>
    <child link="xMateSR4C_link3"/>
    <limit effort="300" lower="-2.96555" upper="2.35619" velocity="10"/>
    <axis xyz="0 -1 0"/>
    <origin rpy="0 0 0" xyz="0.05 0 0.4"/>
  </joint>
  <transmission name="tran3">
    <type>transmission_interface/SimpleTransmission</type>
    <joint name="xmate_joint_3">
      <hardwareInterface>EffortJointInterface</hardwareInterface>
    </joint>
    <actuator name="motor3">
      <hardwareInterface>EffortJointInterface</hardwareInterface>
      <mechanicalReduction>1</mechanicalReduction>
    </actuator>
  </transmission>

  <!--${nameofManipulator}_link 3-->
  <link name="xMateSR4C_link3">
    <visual>
      <geometry>
        <mesh filename="package://xMateSR4C_description/meshes/visual/xMateSR4C_link3.stl" scale="0.001 0.001 0.001"/>
      </geometry>
      <origin rpy="0 0 0" xyz="0 0 0"/>
      <material name="white"/>
    </visual>
    <inertial>
      <origin xyz="-0.00101677311184785 0.0992317670799201 -0.00599764278732221" rpy="0 0 0"/>
      <mass value="1.55161965449885"/>
      <inertia ixx="0.0205839772508243" ixy="0.0034186607558711" ixz="0.000323904256666548" iyy="0.00322986952841047" iyz="0.00178215039218484" izz="0.0202148376332874"/>
    </inertial>
    <collision>
      <geometry>
        <mesh filename="package://xMateSR4C_description/meshes/collision/xMateSR4C_link3.stl" scale="0.001 0.001 0.001"/>
      </geometry>
      <origin rpy="0 0 0" xyz="0 0 0"/>
    </collision>
  </link>

  <joint name="xmate_joint_4" type="revolute">
    <parent link="xMateSR4C_link3"/>
    <child link="xMateSR4C_link4"/>
    <limit effort="300" lower="-3.1416" upper="3.1416" velocity="10"/>
    <!--     lower="-2.79" upper="2.79" -->
    <axis xyz="0 0 1"/>
    <!--     <origin rpy="0 0 0" xyz="0.585 0.0 0.035"/> -->
    <origin rpy="0 0 0" xyz="-0.05 0 0.4"/>
  </joint>
  <transmission name="tran4">
    <type>transmission_interface/SimpleTransmission</type>
    <joint name="xmate_joint_4">
      <hardwareInterface>EffortJointInterface</hardwareInterface>
    </joint>
    <actuator name="motor4">
      <hardwareInterface>EffortJointInterface</hardwareInterface>
      <mechanicalReduction>1</mechanicalReduction>
    </actuator>
  </transmission>

  <!--link 4-->
  <link name="xMateSR4C_link4">
    <visual>
      <geometry>
        <mesh filename="package://xMateSR4C_description/meshes/visual/xMateSR4C_link4.stl" scale=".001 0.001 0.001"/>
      </geometry>
      <origin rpy="0 0 0" xyz="0.0 0.0 0.0"/>
      <material name="white"/>
    </visual>
    <inertial>
      <origin xyz="-2.50011383739252e-05 -0.0109230011023275 -0.071266999970154" rpy="0 0 0"/>
      <mass value="1.8819999954753"/>
      <inertia ixx="0.0133198499755109" ixy="-1.85000009038544e-06" ixz="8.69999115245914e-07" iyy="0.0125198899767503" iyz="-0.00143893999778065" izz="0.00278827999533888"/>
    </inertial>
    <collision>
      <geometry>
        <mesh filename="package://xMateSR4C_description/meshes/collision/xMateSR4C_link4.stl" scale="0.001 0.001 0.001"/>
      </geometry>
      <origin rpy="0 0 0" xyz="0.0 0.0 0.0"/>
    </collision>
  </link>

  <joint name="xmate_joint_5" type="revolute">
    <parent link="xMateSR4C_link4"/>
    <child link="xMateSR4C_link5"/>
    <limit effort="300" lower="-3.1416" upper="3.1416" velocity="10"/>
    <axis xyz="0 -1 0"/>
    <origin rpy="0 0 0" xyz="0 0.136 0"/>
  </joint>
  <transmission name="tran5">
    <type>transmission_interface/SimpleTransmission</type>
    <joint name="xmate_joint_5">
      <hardwareInterface>EffortJointInterface</hardwareInterface>
    </joint>
    <actuator name="motor5">
      <hardwareInterface>EffortJointInterface</hardwareInterface>
      <mechanicalReduction>1</mechanicalReduction>
    </actuator>
  </transmission>

  <!--link 5-->
  <link name="xMateSR4C_link5">
    <visual>
      <geometry>
        <mesh filename="package://xMateSR4C_description/meshes/visual/xMateSR4C_link5.stl" scale="0.001 0.001 0.001"/>
      </geometry>
      <origin rpy="0 0 0" xyz="0 0 0"/>
      <material name="white"/>
    </visual>
    <inertial>
      <origin xyz="-0.00141300709545952 0.0118448713738878 -0.0209142000136706" rpy="0 0 0"/>
      <mass value="1.34621855234916"/>
      <inertia ixx="0.00490782058915933" ixy="-1.04779487811945e-05" ixz="-9.95872429112993e-06" iyy="0.00384857289176222" iyz="0.000384368912752211" izz="0.00258053503197348"/>
    </inertial>
    <collision>
      <geometry>
        <mesh filename="package://xMateSR4C_description/meshes/collision/xMateSR4C_link5.stl" scale="0.001 0.001 0.001"/>
      </geometry>
      <origin rpy="0 0 0" xyz="0 0 0"/>
    </collision>
  </link>

  <joint name="xmate_joint_6" type="revolute">
    <parent link="xMateSR4C_link5"/>
    <child link="xMateSR4C_link6"/>
    <limit effort="300" lower="-3.14" upper="3.14" velocity="10"/>
    <axis xyz="0 0 1"/>
    <origin rpy="0.0 0.0 0" xyz="0 0 0.1035"/>
  </joint>
  <transmission name="tran6">
    <type>transmission_interface/SimpleTransmission</type>
    <joint name="xmate_joint_6">
      <hardwareInterface>EffortJointInterface</hardwareInterface>
    </joint>
    <actuator name="motor6">
      <hardwareInterface>EffortJointInterface</hardwareInterface>
      <mechanicalReduction>1</mechanicalReduction>
    </actuator>
  </transmission>

  <!--link 6-->
  <link name="xMateSR4C_link6">
    <visual>
      <geometry>
        <mesh filename="package://xMateSR4C_description/meshes/visual/xMateSR4C_link6.stl" scale="0.001 0.001 0.001"/>
      </geometry>
      <origin rpy="0 0 0" xyz="0.0 0.0 0.0"/>
      <material name="white"/>
    </visual>
    <inertial>
      <origin xyz="7.29993135608786e-05 7.90001800890199e-05 -0.044852999792348" rpy="0 0 0"/>
      <mass value="0.633999997351584"/>
      <inertia ixx="0.000997019998284638" ixy="-1.37999999641383e-06" ixz="8.99999979434996e-07" iyy="0.00100252999827485" iyz="1.5800000042753e-06" izz="0.000447949999234091"/>
    </inertial>
    <collision>
      <geometry>
        <mesh filename="package://xMateSR4C_description/meshes/collision/xMateSR4C_link6.stl" scale="0.001 0.001 0.001"/>
      </geometry>
      <origin rpy="0 0 0" xyz="0.0 0.0 0.0"/>
    </collision>
  </link>
</robot>